Workbook

Sheet Jan
B1: Dia | C1: Lojas | D1: Faturamento dia | E1: Não pago dia | F1: Recebido dia | G1: Não pago Acumulado | H1: Peças | I1: Dia | J1: Lojas | K1: Faturamento | L1: Não pago dia | M1: Recebido dia | N1: Não pago Acumulado | O1: Peças | P1: Dia | Q1: Lojas | R1: Faturamento | S1: Não pago dia | T1: Recebido dia | U1: Não pago Acumulado | V1: Peças | W1: Dia | X1: Lojas | Y1: Faturamento | Z1: Não pago dia | AA1: Recebido dia | AB1: Não pago Acumulado | AC1: Peças | AD1: Dia | AE1: Lojas | AF1: Faturamento | AG1: Não pago dia | AH1: Recebido dia | AI1: Não pago Acumulado | AJ1: Peças | AM1: Lojas | AN1: Faturamento | AO1: Não pago dia | AP1: Recebido | AQ1: Peças
A2: Segunda-feira | C2: Lago Norte | I2: 45662 | J2: Lago Norte | K2: 1111.6 | L2: 267.7 | M2: 843.9 | N2: 2401.14 | O2: 42 | P2: 45669 | Q2: Lago Norte | R2: 907.3 | S2: 0 | T2: 1065.79 | U2: 1003.75 | V2: 29 | W2: 45676 | X2: Lago Norte | Y2: =848.6-36 -> 812.6 | Z2: 0 | AA2: 1415.35 | AB2: 597 | AC2: 35 | AD2: 45683 | AE2: Lago Norte | AF2: 1510.1 | AG2: 41.2 | AH2: 1594.9 | AI2: 1009.2 | AJ2: 49 | AL2: Faturamento Total das Segundas-feiras | AM2: Lago Norte | AN2: =D2+K2+R2+Y2+AF2 -> 4341.6 | AO2: =E2+L2+S2+Z2+AG2 -> 308.9 | AP2: =F2+M2+T2+AA2+AH2 -> 4919.94 | AQ2: =H2+O2+V2+AC2+AJ2 -> 155
C3: 202 Norte | J3: 202 Norte | K3: 1787 | L3: 267 | M3: 1770.9 | N3: 813.7 | O3: 47 | Q3: 202 Norte | R3: 316.9 | S3: 184 | T3: 132.9 | U3: 1423.6 | V3: 23 | X3: 202 Norte | Y3: 841 | Z3: 18 | AA3: 823 | AB3: 1401.5 | AC3: 46 | AE3: 202 Norte | AF3: 1543.8 | AG3: 1127.8 | AH3: 470.9 | AI3: 2626.4 | AJ3: 73 | AM3: 202 Norte | AN3: =D3+K3+R3+Y3+AF3 -> 4488.7 | AO3: =E3+L3+S3+Z3+AG3 -> 1596.8 | AP3: =F3+M3+T3+AA3+AH3 -> 3197.7 | AQ3: =H3+O3+V3+AC3+AJ3 -> 189
C4: 213 / Sof | J4: 213 / Sof | Q4: 213 Norte | X4: 213 Norte | AE4: 213 Norte | AM4: 213 Norte | AN4: =D4+K4+R4+Y4+AF4 -> 0 | AO4: =E4+L4+S4+Z4+AG4 -> 0 | AP4: =F4+M4+T4+AA4+AH4 -> 0 | AQ4: =H4+O4+V4+AC4+AJ4 -> 0
C5: 307 Norte | J5: 307 Norte | K5: 2497 | L5: 172 | M5: 2949.9 | N5: 6258.53 | O5: 83 | Q5: 307 Norte | R5: 3286.61 | S5: 1090.4 | T5: 2196.21 | U5: 6092.57 | V5: 93 | X5: 307 Norte | Y5: 2219.52 | Z5: 435.11 | AA5: 2059.41 | AB5: 5791.48 | AC5: 93 | AE5: 307 Norte | AF5: 3496.62 | AG5: 343.95 | AH5: 3420.67 | AI5: 6553.03 | AJ5: 119 | AM5: 307 Norte | AN5: =D5+K5+R5+Y5+AF5 -> 11499.75 | AO5: =E5+L5+S5+Z5+AG5 -> 2041.46 | AP5: =F5+M5+T5+AA5+AH5 -> 10626.19 | AQ5: =H5+O5+V5+AC5+AJ5 -> 388
C6: 313 Norte | J6: 313 Norte | K6: 2004.9 | L6: 0 | M6: 2004.9 | N6: 1295.9 | O6: 79 | Q6: 313 Norte | R6: 930 | S6: 0 | T6: 970 | U6: 1044.9 | V6: 27 | X6: 313 Norte | Y6: 1937.6 | Z6: 0 | AA6: 1937.6 | AB6: 1389.35 | AC6: 62 | AE6: 313 Norte | AF6: 1482.7 | AG6: 0 | AH6: 1482.7 | AI6: 1674.35 | AJ6: 53 | AM6: 313 Norte | AN6: =D6+K6+R6+Y6+AF6 -> 6355.2 | AO6: =E6+L6+S6+Z6+AG6 -> 0 | AP6: =F6+M6+T6+AA6+AH6 -> 6395.2 | AQ6: =H6+O6+V6+AC6+AJ6 -> 221
C7: 314 Sul | J7: 314 Sul | K7: 0 | L7: 0 | M7: 0 | N7: 584.7 | O7: 11 | Q7: 314 Sul | U7: 384.7 | X7: 314 Sul | AB7: 384.7 | AE7: 314 Sul | AM7: 314 Sul | AN7: =D7+K7+R7+Y7+AF7 -> 0 | AO7: =E7+L7+S7+Z7+AG7 -> 0 | AP7: =F7+M7+T7+AA7+AH7 -> 0 | AQ7: =H7+O7+V7+AC7+AJ7 -> 11
C8: Sudoeste | J8: Sudoeste | K8: 729.6 | L8: 255.8 | M8: 473.8 | N8: 2380.24 | O8: 30 | Q8: Sudoeste | R8: 2305 | S8: 490 | T8: 1865 | U8: 2737.34 | V8: 74 | X8: Sudoeste | Y8: 1278.9 | Z8: 233.9 | AA8: 1409 | AB8: 2516.74 | AC8: 49 | AE8: Sudoeste | AF8: 1279.8 | AG8: 462.8 | AH8: 1262.9 | AI8: 2665.59 | AJ8: 91 | AM8: Sudoeste | AN8: =D8+K8+R8+Y8+AF8 -> 5593.3 | AO8: =E8+L8+S8+Z8+AG8 -> 1442.5 | AP8: =F8+M8+T8+AA8+AH8 -> 5010.7 | AQ8: =H8+O8+V8+AC8+AJ8 -> 244
C9: Noroeste | J9: Noroeste | K9: 2932.95 | L9: 365.9 | M9: 3138.85 | N9: 5895.06 | O9: 121 | Q9: Noroeste | R9: 3576.8 | S9: 371.7 | T9: 3037.7 | U9: 6519.73 | V9: 125 | X9: Noroeste | Y9: 4230.57 | Z9: 529 | AA9: 4981.47 | AB9: 6080.83 | AC9: 116 | AE9: Noroeste | AF9: 3715.88 | AG9: 322.28 | AH9: 3634.4 | AI9: 6189.11 | AJ9: 141 | AM9: Noroeste | AN9: =D9+K9+R9+Y9+AF9 -> 14456.2 | AO9: =E9+L9+S9+Z9+AG9 -> 1588.88 | AP9: =F9+M9+T9+AA9+AH9 -> 14792.42 | AQ9: =H9+O9+V9+AC9+AJ9 -> 503
C10: Total: | D10: =D2+D3+D4+D5+D6+D7+D8+D9 -> 0 | E10: =E2+E3+E4+E5+E6+E7+E8+E9 -> 0 | F10: =F2+F3+F4+F5+F6+F7+F8+F9 -> 0 | G10: =G2+G3+G4+G5+G6+G7+G8+G9 -> 0 | H10: =H2+H3+H4+H5+H6+H7+H8+H9 -> 0 | J10: Total: | K10: =K2+K3+K4+K5+K6+K7+K8+K9 -> 11063.05 | L10: =L2+L3+L4+L5+L6+L7+L8+L9 -> 1328.4 | M10: =M2+M3+M4+M5+M6+M7+M8+M9 -> 11182.25 | N10: =N2+N3+N4+N5+N6+N7+N8+N9 -> 19629.27 | O10: =O2+O3+O4+O5+O6+O7+O8+O9 -> 413 | Q10: Total: | R10: =R2+R3+R4+R5+R6+R7+R8+R9 -> 11322.61 | S10: =S2+S3+S4+S5+S6+S7+S8+S9 -> 2136.1 | T10: =T2+T3+T4+T5+T6+T7+T8+T9 -> 9267.6 | U10: =U2+U3+U4+U5+U6+U7+U8+U9 -> 19206.59 | V10: =V2+V3+V4+V5+V6+V7+V8+V9 -> 371 | X10: Total: | Y10: =Y2+Y3+Y4+Y5+Y6+Y7+Y8+Y9 -> 11320.19 | Z10: =Z2+Z3+Z4+Z5+Z6+Z7+Z8+Z9 -> 1216.01 | AA10: =AA2+AA3+AA4+AA5+AA6+AA7+AA8+AA9 -> 12625.83 | AB10: =AB2+AB3+AB4+AB5+AB6+AB7+AB8+AB9 -> 18161.6 | AC10: =AC2+AC3+AC4+AC5+AC6+AC7+AC8+AC9 -> 401 | AE10: Total: | AF10: =AF2+AF3+AF4+AF5+AF6+AF7+AF8+AF9 -> 13028.9 | AG10: =AG2+AG3+AG4+AG5+AG6+AG7+AG8+AG9 -> 2298.03 | AH10: =AH2+AH3+AH4+AH5+AH6+AH7+AH8+AH9 -> 11866.47 | AI10: =AI2+AI3+AI4+AI5+AI6+AI7+AI8+AI9 -> 20717.68 | AJ10: =AJ2+AJ3+AJ4+AJ5+AJ6+AJ7+AJ8+AJ9 -> 526 | AM10: Total: | AN10: =AN2+AN3+AN4+AN5+AN6+AN7+AN8+AN9 -> 46734.75 | AO10: =AO2+AO3+AO4+AO5+AO6+AO7+AO8+AO9 -> 6978.54 | AP10: =AP2+AP3+AP4+AP5+AP6+AP7+AP8+AP9 -> 44942.15 | AQ10: =AQ2+AQ3+AQ4+AQ5+AQ6+AQ7+AQ8+AQ9 -> 1711
C11: Faturado dia real | D11: =D10-E10 -> 0 | J11: Faturado dia real | K11: =K10-L10 -> 9734.65 | Q11: Faturado dia real | R11: =R10-S10 -> 9186.51 | X11: Faturado dia real | Y11: =Y10-Z10 -> 10104.18 | AE11: Faturado dia real | AF11: =AF10-AG10 -> 10730.87 | AM11: Fat. Real | AN11: =AN10-AO10 -> 39756.21
C12: Recebido dia real | D12: =F10-E10 -> 0 | J12: Recebido dia real | K12: =M10-L10 -> 9853.85 | Q12: Recebido dia real | R12: =T10-S10 -> 7131.5 | X12: Recebido dia real | Y12: =AA10-Z10 -> 11409.82 | AE12: Recebido dia real | AF12: =AH10-AG10 -> 9568.44
B13: Dia | C13: Lojas | D13: Faturamento dia | E13: Não pago dia | F13: Recebido dia | G13: Não pago Acumulado | H13: Peças | I13: Dia | J13: Lojas | K13: Faturamento | L13: Não pago dia | M13: Recebido dia | N13: Não pago Acumulado | O13: Peças | P13: Dia | Q13: Lojas | R13: Faturamento | S13: Não pago dia | T13: Recebido dia | U13: Não pago Acumulado | V13: Peças | W13: Dia | X13: Lojas | Y13: Faturamento | Z13: Não pago dia | AA13: Recebido dia | AB13: Não pago Acumulado | AC13: Peças | AD13: Dia | AE13: Lojas | AF13: Faturamento | AG13: Não pago dia | AH13: Recebido dia | AI13: Não pago Acumulado | AJ13: Peças | AM13: Lojas | AN13: Faturamento | AO13: Não pago dia | AP13: Recebido | AQ13: Peças
A14: Terça-feira | C14: Lago Norte | I14: 45663 | J14: Lago Norte | K14: 284 | L14: 0 | M14: 287 | N14: 2401.14 | O14: 16 | P14: 45670 | Q14: Lago Norte | R14: 38.2 | S14: 0 | T14: 38.28 | U14: 1003.75 | V14: 6 | W14: 45677 | X14: Lago Norte | Y14: 807.8 | Z14: 140 | AA14: 667.8 | AB14: 737 | AC14: 29 | AD14: 45684 | AE14: Lago Norte | AF14: 693.5 | AG14: 163 | AH14: 637.7 | AI14: 1065 | AJ14: 37 | AL14: Faturamento Total das Terças-feiras | AM14: Lago Norte | AN14: =D14+K14+R14+Y14+AF14 -> 1823.5 | AO14: =E14+L14+S14+Z14+AG14 -> 303 | AP14: =F14+M14+T14+AA14+AH14 -> 1630.78 | AQ14: =H14+O14+V14+AC14+AJ14 -> 88
C15: 202 Norte | J15: 202 Norte | K15: 199 | L15: 0 | M15: 199 | N15: 813.7 | O15: 7 | Q15: 202 Norte | R15: 179.8 | S15: 139.8 | T15: 156.9 | U15: 1446.5 | V15: 4 | X15: 202 Norte | Y15: 420 | Z15: 96 | AA15: 324 | AB15: 1497.5 | AC15: 17 | AE15: 202 Norte | AF15: 568 | AG15: 68 | AH15: 1086.9 | AI15: 2107.5 | AJ15: 10 | AM15: 202 Norte | AN15: =D15+K15+R15+Y15+AF15 -> 1366.8 | AO15: =E15+L15+S15+Z15+AG15 -> 303.8 | AP15: =F15+M15+T15+AA15+AH15 -> 1766.8 | AQ15: =H15+O15+V15+AC15+AJ15 -> 38
C16: 213 / Sof | J16: 213 / Sof | Q16: 213 Norte | X16: 213 Norte | AE16: 213 Norte | AM16: 213 Norte | AN16: =D16+K16+R16+Y16+AF16 -> 0 | AO16: =E16+L16+S16+Z16+AG16 -> 0 | AP16: =F16+M16+T16+AA16+AH16 -> 0 | AQ16: =H16+O16+V16+AC16+AJ16 -> 0
C17: 307 Norte | J17: 307 Norte | K17: 1066.9 | L17: 132.9 | M17: 934 | N17: 6391.43 | O17: 31 | Q17: 307 Norte | R17: 1717 | S17: 165.6 | T17: 1817.4 | U17: 5992.17 | V17: 74 | X17: 307 Norte | Y17: 2471.7 | Z17: 512.9 | AA17: 2164.8 | AB17: 6098.38 | AC17: 59 | AE17: 307 Norte | AF17: 711.9 | AG17: 94 | AH17: 787.9 | AI17: 6477.03 | AJ17: 36 | AM17: 307 Norte | AN17: =D17+K17+R17+Y17+AF17 -> 5967.5 | AO17: =E17+L17+S17+Z17+AG17 -> 905.4 | AP17: =F17+M17+T17+AA17+AH17 -> 5704.1 | AQ17: =H17+O17+V17+AC17+AJ17 -> 200
C18: 313 Norte | J18: 313 Norte | K18: 1144 | L18: 40 | M18: 1204 | N18: 1235.9 | O18: 65 | Q18: 313 Norte | R18: 2122.25 | S18: 662.35 | T18: 1459.9 | U18: 1707.25 | V18: 99 | X18: 313 Norte | Y18: 1070 | Z18: 132 | AA18: 982 | AB18: 1477.35 | AC18: 52 | AE18: 313 Norte | AF18: 755.8 | AG18: 0 | AH18: 755.8 | AI18: 1674.35 | AJ18: 30 | AM18: 313 Norte | AN18: =D18+K18+R18+Y18+AF18 -> 5092.05 | AO18: =E18+L18+S18+Z18+AG18 -> 834.35 | AP18: =F18+M18+T18+AA18+AH18 -> 4401.7 | AQ18: =H18+O18+V18+AC18+AJ18 -> 246
C19: 314 Sul | J19: 314 Sul | K19: 0 | L19: 0 | M19: 0 | N19: 584.7 | O19: 0 | Q19: 314 Sul | U19: 384.7 | X19: 314 Sul | AE19: 314 Sul | AM19: 314 Sul | AN19: =D19+K19+R19+Y19+AF19 -> 0 | AO19: =E19+L19+S19+Z19+AG19 -> 0 | AP19: =F19+M19+T19+AA19+AH19 -> 0 | AQ19: =H19+O19+V19+AC19+AJ19 -> 0
C20: Sudoeste | J20: Sudoeste | K20: 742.9 | L20: 397 | M20: 387.9 | N20: 2735.24 | O20: 41 | Q20: Sudoeste | R20: 708 | S20: 32 | T20: 980 | U20: 2465.34 | V20: 29 | X20: Sudoeste | Y20: 459.05 | Z20: 113.35 | AA20: 345.7 | AB20: 2630.09 | AC20: 21 | AE20: Sudoeste | AF20: 604.9 | AG20: 177 | AH20: 774.9 | AI20: 2495.59 | AJ20: 18 | AM20: Sudoeste | AN20: =D20+K20+R20+Y20+AF20 -> 2514.85 | AO20: =E20+L20+S20+Z20+AG20 -> 719.35 | AP20: =F20+M20+T20+AA20+AH20 -> 2488.5 | AQ20: =H20+O20+V20+AC20+AJ20 -> 109
C21: Noroeste | J21: Noroeste | K21: 1412.1 | L21: 120.4 | M21: 1493.2 | N21: 5813.96 | O21: 63 | Q21: Noroeste | R21: 1968.5 | S21: 258.8 | T21: 1904.7 | U21: 6583.53 | V21: 96 | X21: Noroeste | Y21: 1581.5 | Z21: 109.7 | AA21: 1753.7 | AB21: 5908.63 | AC21: 97 | AE21: Noroeste | AF21: 2856.5 | AG21: 0 | AH21: 3002.7 | AI21: 5992.31 | AJ21: 116 | AM21: Noroeste | AN21: =D21+K21+R21+Y21+AF21 -> 7818.6 | AO21: =E21+L21+S21+Z21+AG21 -> 488.9 | AP21: =F21+M21+T21+AA21+AH21 -> 8154.3 | AQ21: =H21+O21+V21+AC21+AJ21 -> 372
C22: Total: | D22: =D14+D15+D16+D17+D18+D19+D20+D21 -> 0 | E22: =E14+E15+E16+E17+E18+E19+E20+E21 -> 0 | F22: =F14+F15+F16+F17+F18+F19+F20+F21 -> 0 | G22: =G14+G15+G16+G17+G18+G19+G20+G21 -> 0 | H22: =H14+H15+H16+H17+H18+H19+H20+H21 -> 0 | J22: Total: | K22: =K14+K15+K16+K17+K18+K19+K20+K21 -> 4848.9 | L22: =L14+L15+L16+L17+L18+L19+L20+L21 -> 690.3 | M22: =M14+M15+M16+M17+M18+M19+M20+M21 -> 4505.1 | N22: =N14+N15+N16+N17+N18+N19+N20+N21 -> 19976.07 | O22: =O14+O15+O16+O17+O18+O19+O20+O21 -> 223 | Q22: Total: | R22: =R14+R15+R16+R17+R18+R19+R20+R21 -> 6733.75 | S22: =S14+S15+S16+S17+S18+S19+S20+S21 -> 1258.55 | T22: =T14+T15+T16+T17+T18+T19+T20+T21 -> 6357.18 | U22: =U14+U15+U16+U17+U18+U19+U20+U21 -> 19583.24 | V22: =V14+V15+V16+V17+V18+V19+V20+V21 -> 308 | X22: Total: | Y22: =Y14+Y15+Y16+Y17+Y18+Y19+Y20+Y21 -> 6810.05 | Z22: =Z14+Z15+Z16+Z17+Z18+Z19+Z20+Z21 -> 1103.95 | AA22: =AA14+AA15+AA16+AA17+AA18+AA19+AA20+AA21 -> 6238 | AB22: =AB14+AB15+AB16+AB17+AB18+AB19+AB20+AB21 -> 18348.95 | AC22: =AC14+AC15+AC16+AC17+AC18+AC19+AC20+AC21 -> 275 | AE22: Total: | AF22: =AF14+AF15+AF16+AF17+AF18+AF19+AF20+AF21 -> 6190.6 | AG22: =AG14+AG15+AG16+AG17+AG18+AG19+AG20+AG21 -> 502 | AH22: =AH14+AH15+AH16+AH17+AH18+AH19+AH20+AH21 -> 7045.9 | AI22: =AI14+AI15+AI16+AI17+AI18+AI19+AI20+AI21 -> 19811.78 | AJ22: =AJ14+AJ15+AJ16+AJ17+AJ18+AJ19+AJ20+AJ21 -> 247 | AM22: Total: | AN22: =AN14+AN15+AN16+AN17+AN18+AN19+AN20+AN21 -> 24583.3 | AO22: =AO14+AO15+AO16+AO17+AO18+AO19+AO20+AO21 -> 3554.8 | AP22: =AP14+AP15+AP16+AP17+AP18+AP19+AP20+AP21 -> 24146.18 | AQ22: =AQ14+AQ15+AQ16+AQ17+AQ18+AQ19+AQ20+AQ21 -> 1053
C23: Faturado dia real | D23: =D22-E22 -> 0 | J23: Faturado dia real | K23: =K22-L22 -> 4158.6 | Q23: Faturado dia real | R23: =R22-S22 -> 5475.2 | X23: Faturado dia real | Y23: =Y22-Z22 -> 5706.1 | AE23: Faturado dia real | AF23: =AF22-AG22 -> 5688.6 | AM23: Fat. Real | AN23: =AN22-AO22 -> 21028.5
C24: Recebido dia real | D24: =F22-E22 -> 0 | J24: Recebido dia real | K24: =M22-L22 -> 3814.8 | Q24: Recebido dia real | R24: =T22-S22 -> 5098.63 | X24: Recebido dia real | Y24: =AA22-Z22 -> 5134.05 | AE24: Recebido dia real | AF24: =AH22-AG22 -> 6543.9
B25: Dia | C25: Lojas | D25: Faturamento dia | E25: Não pago dia | F25: Recebido dia | G25: Não pago Acumulado | H25: Peças | I25: Dia | J25: Lojas | K25: Faturamento | L25: Não pago dia | M25: Recebido dia | N25: Não pago Acumulado | O25: Peças | P25: Dia | Q25: Lojas | R25: Faturamento | S25: Não pago dia | T25: Recebido dia | U25: Não pago Acumulado | V25: Peças | W25: Dia | X25: Lojas | Y25: Faturamento | Z25: Não pago dia | AA25: Recebido dia | AB25: Não pago Acumulado | AC25: Peças | AD25: Dia | AE25: Lojas | AF25: Faturamento | AG25: Não pago dia | AH25: Recebido dia | AI25: Não pago Acumulado | AJ25: Peças | AM25: Lojas | AN25: Faturamento | AO25: Não pago dia | AP25: Recebido | AQ25: Peças
A26: Quarta-feira | C26: Lago Norte | I26: 45664 | J26: Lago Norte | K26: 1706.73 | L26: 392.7 | M26: 1314.03 | N26: 2793.84 | O26: 60 | P26: 45671 | Q26: Lago Norte | R26: 1263.8 | S26: 0 | T26: 1263.8 | U26: 1003.75 | V26: 28 | W26: 45678 | X26: Lago Norte | Y26: 935.9 | Z26: 104.9 | AA26: 831 | AB26: 841.9 | AC26: 31 | AD26: 45685 | AE26: Lago Norte | AF26: 889 | AG26: 0 | AH26: 1173 | AI26: 781 | AJ26: 28 | AL26: Faturamento Total das Quartas-feiras | AM26: Lago Norte | AN26: =D26+K26+R26+Y26+AF26 -> 4795.43 | AO26: =E26+L26+S26+Z26+AG26 -> 497.6 | AP26: =F26+M26+T26+AA26+AH26 -> 4581.83 | AQ26: =H26+O26+V26+AC26+AJ26 -> 147
C27: 202 Norte | J27: 202 Norte | K27: 511.9 | L27: 167.9 | M27: 365 | N27: 960.6 | O27: 43 | Q27: 202 Norte | R27: 731 | S27: 73 | T27: 676 | U27: 1501.5 | V27: 45 | X27: 202 Norte | Y27: 374.9 | Z27: 90 | AA27: 284.9 | AB27: 1587.5 | AC27: 20 | AE27: 202 Norte | AF27: 665.8 | AG27: 0 | AH27: 665.8 | AI27: 2107.5 | AJ27: 34 | AM27: 202 Norte | AN27: =D27+K27+R27+Y27+AF27 -> 2283.6 | AO27: =E27+L27+S27+Z27+AG27 -> 330.9 | AP27: =F27+M27+T27+AA27+AH27 -> 1991.7 | AQ27: =H27+O27+V27+AC27+AJ27 -> 142
C28: 213 / Sof | J28: 213 / Sof | Q28: 213 Norte | X28: 213 Norte | AE28: 213 Norte | AM28: 213 Norte | AN28: =D28+K28+R28+Y28+AF28 -> 0 | AO28: =E28+L28+S28+Z28+AG28 -> 0 | AP28: =F28+M28+T28+AA28+AH28 -> 0 | AQ28: =H28+O28+V28+AC28+AJ28 -> 0
C29: 307 Norte | J29: 307 Norte | K29: 1431.18 | L29: 185 | M29: 2073.34 | N29: 5749.27 | O29: 68 | Q29: 307 Norte | R29: 467.7 | S29: 0 | T29: 815.6 | U29: 5644.27 | V29: 27 | X29: 307 Norte | Y29: 2320.95 | Z29: 861.8 | AA29: 1943.55 | AB29: 6475.78 | AC29: 84 | AE29: 307 Norte | AF29: 3410.2 | AG29: 34.9 | AH29: 4782.7 | AI29: 5104.53 | AJ29: 82 | AM29: 307 Norte | AN29: =D29+K29+R29+Y29+AF29 -> 7630.03 | AO29: =E29+L29+S29+Z29+AG29 -> 1081.7 | AP29: =F29+M29+T29+AA29+AH29 -> 9615.19 | AQ29: =H29+O29+V29+AC29+AJ29 -> 261
C30: 313 Norte | J30: 313 Norte | K30: 1106.9 | L30: 0 | M30: 1106.9 | N30: 1235.9 | O30: 47 | Q30: 313 Norte | R30: 1192 | S30: 0 | T30: 1246.9 | U30: 1652.35 | V30: 51 | X30: 313 Norte | Y30: 560.6 | Z30: 119 | AA30: 441.6 | AB30: 1596.35 | AC30: 19 | AE30: 313 Norte | AF30: 1473 | AG30: 110 | AH30: 1363 | AI30: 1784.35 | AJ30: 60 | AM30: 313 Norte | AN30: =D30+K30+R30+Y30+AF30 -> 4332.5 | AO30: =E30+L30+S30+Z30+AG30 -> 229 | AP30: =F30+M30+T30+AA30+AH30 -> 4158.4 | AQ30: =H30+O30+V30+AC30+AJ30 -> 177
C31: 314 Sul | J31: 314 Sul | K31: 0 | L31: 0 | M31: 0 | N31: 584.7 | O31: 10 | Q31: 314 Sul | U31: 384.7 | X31: 314 Sul | AE31: 314 Sul | AM31: 314 Sul | AN31: =D31+K31+R31+Y31+AF31 -> 0 | AO31: =E31+L31+S31+Z31+AG31 -> 0 | AP31: =F31+M31+T31+AA31+AH31 -> 0 | AQ31: =H31+O31+V31+AC31+AJ31 -> 10
C32: Sudoeste | J32: Sudoeste | K32: 756.3 | L32: 50 | M32: 1009.2 | N32: 2482.34 | O32: 21 | Q32: Sudoeste | R32: 505 | S32: 265 | T32: 240 | U32: 2730.34 | V32: 22 | X32: Sudoeste | Y32: 568.8 | Z32: 49 | AA32: 519.8 | AB32: 2679.09 | AC32: 40 | AE32: Sudoeste | AF32: 785.9 | AG32: 30 | AH32: 909.2 | AI32: 2372.29 | AJ32: 28 | AM32: Sudoeste | AN32: =D32+K32+R32+Y32+AF32 -> 2616 | AO32: =E32+L32+S32+Z32+AG32 -> 394 | AP32: =F32+M32+T32+AA32+AH32 -> 2678.2 | AQ32: =H32+O32+V32+AC32+AJ32 -> 111
C33: Noroeste | J33: Noroeste | K33: 1596.7 | L33: 353 | M33: 1989.5 | N33: 5421.16 | O33: 82 | Q33: Noroeste | R33: 1740.7 | S33: 0 | T33: 2102.5 | U33: 6218.73 | V33: 83 | X33: Noroeste | Y33: 3191.05 | Z33: 391.7 | AA33: 3190.65 | AB33: 5909.03 | AC33: 98 | AE33: Noroeste | AF33: 2245.7 | AG33: 304 | AH33: 2221.4 | AI33: 6016.61 | AJ33: 113 | AM33: Noroeste | AN33: =D33+K33+R33+Y33+AF33 -> 8774.15 | AO33: =E33+L33+S33+Z33+AG33 -> 1048.7 | AP33: =F33+M33+T33+AA33+AH33 -> 9504.05 | AQ33: =H33+O33+V33+AC33+AJ33 -> 376
C34: Total: | D34: =D26+D27+D28+D29+D30+D31+D32+D33 -> 0 | E34: =E26+E27+E28+E29+E30+E31+E32+E33 -> 0 | F34: =F26+F27+F28+F29+F30+F31+F32+F33 -> 0 | G34: =G26+G27+G28+G29+G30+G31+G32+G33 -> 0 | H34: =H26+H27+H28+H29+H30+H31+H32+H33 -> 0 | J34: Total: | K34: =K26+K27+K28+K29+K30+K31+K32+K33 -> 7109.71 | L34: =L26+L27+L28+L29+L30+L31+L32+L33 -> 1148.6 | M34: =M26+M27+M28+M29+M30+M31+M32+M33 -> 7857.97 | N34: =N26+N27+N28+N29+N30+N31+N32+N33 -> 19227.81 | O34: =O26+O27+O28+O29+O30+O31+O32+O33 -> 331 | Q34: Total: | R34: =R26+R27+R28+R29+R30+R31+R32+R33 -> 5900.2 | S34: =S26+S27+S28+S29+S30+S31+S32+S33 -> 338 | T34: =T26+T27+T28+T29+T30+T31+T32+T33 -> 6344.8 | U34: =U26+U27+U28+U29+U30+U31+U32+U33 -> 19135.64 | V34: =V26+V27+V28+V29+V30+V31+V32+V33 -> 256 | X34: Total: | Y34: =Y26+Y27+Y28+Y29+Y30+Y31+Y32+Y33 -> 7952.2 | Z34: =Z26+Z27+Z28+Z29+Z30+Z31+Z32+Z33 -> 1616.4 | AA34: =AA26+AA27+AA28+AA29+AA30+AA31+AA32+AA33 -> 7211.5 | AB34: =AB26+AB27+AB28+AB29+AB30+AB31+AB32+AB33 -> 19089.65 | AC34: =AC26+AC27+AC28+AC29+AC30+AC31+AC32+AC33 -> 292 | AE34: Total: | AF34: =AF26+AF27+AF28+AF29+AF30+AF31+AF32+AF33 -> 9469.6 | AG34: =AG26+AG27+AG28+AG29+AG30+AG31+AG32+AG33 -> 478.9 | AH34: =AH26+AH27+AH28+AH29+AH30+AH31+AH32+AH33 -> 11115.1 | AI34: =AI26+AI27+AI28+AI29+AI30+AI31+AI32+AI33 -> 18166.28 | AJ34: =AJ26+AJ27+AJ28+AJ29+AJ30+AJ31+AJ32+AJ33 -> 345 | AM34: Total: | AN34: =AN26+AN27+AN28+AN29+AN30+AN31+AN32+AN33 -> 30431.71 | AO34: =AO26+AO27+AO28+AO29+AO30+AO31+AO32+AO33 -> 3581.9 | AP34: =AP26+AP27+AP28+AP29+AP30+AP31+AP32+AP33 -> 32529.37 | AQ34: =AQ26+AQ27+AQ28+AQ29+AQ30+AQ31+AQ32+AQ33 -> 1224
C35: Faturado dia real | D35: =D34-E34 -> 0 | J35: Faturado dia real | K35: =K34-L34 -> 5961.11 | Q35: Faturado dia real | R35: =R34-S34 -> 5562.2 | X35: Faturado dia real | Y35: =Y34-Z34 -> 6335.8 | AE35: Faturado dia real | AF35: =AF34-AG34 -> 8990.7 | AM35: Fat. Real | AN35: =AN34-AO34 -> 26849.81
C36: Recebido dia real | D36: =F34-E34 -> 0 | J36: Recebido dia real | K36: =M34-L34 -> 6709.37 | Q36: Recebido dia real | R36: =T34-S34 -> 6006.8 | X36: Recebido dia real | Y36: =AA34-Z34 -> 5595.1 | AE36: Recebido dia real | AF36: =AH34-AG34 -> 10636.2
B37: Dia | C37: Lojas | D37: Faturamento dia | E37: Não pago dia | F37: Recebido dia | G37: Não pago Acumulado | H37: Peças | I37: Dia | J37: Lojas | K37: Faturamento | L37: Não pago dia | M37: Recebido dia | N37: Não pago Acumulado | O37: Peças | P37: Dia | Q37: Lojas | R37: Faturamento | S37: Não pago dia | T37: Recebido dia | U37: Não pago Acumulado | V37: Peças | W37: Dia | X37: Lojas | Y37: Faturamento | Z37: Não pago dia | AA37: Recebido dia | AB37: Não pago Acumulado | AC37: Peças | AD37: Dia | AE37: Lojas | AF37: Faturamento | AG37: Não pago dia | AH37: Recebido dia | AI37: Não pago Acumulado | AJ37: Peças | AM37: Lojas | AN37: Faturamento | AO37: Não pago dia | AP37: Recebido | AQ37: Peças
A38: Quinta-feira | B38: 01/01/2025 - Feriado | C38: Lago Norte | I38: 45665 | J38: Lago Norte | K38: 1071.5 | L38: 0 | M38: 1381.3 | N38: 2484.04 | O38: 42 | P38: 45672 | Q38: Lago Norte | R38: 256.7 | S38: 0 | T38: 256.7 | U38: 1003.75 | V38: 6 | W38: 45679 | X38: Lago Norte | Y38: 773 | Z38: 186 | AA38: 587 | AB38: 1027.9 | AC38: 35 | AD38: 45686 | AE38: Lago Norte | AF38: 251 | AG38: 161 | AH38: 90 | AI38: 942 | AJ38: 8 | AL38: Faturamento Total das Quintas-feiras | AM38: Lago Norte | AN38: =D38+K38+R38+Y38+AF38 -> 2352.2 | AO38: =E38+L38+S38+Z38+AG38 -> 347 | AP38: =F38+M38+T38+AA38+AH38 -> 2315 | AQ38: =H38+O38+V38+AC38+AJ38 -> 91
C39: 202 Norte | J39: 202 Norte | K39: 210 | L39: 0 | M39: 231 | N39: 939.6 | O39: 9 | Q39: 202 Norte | R39: 838.56 | S39: 0 | T39: 896.56 | U39: 1443.5 | V39: 34 | X39: 202 Norte | Y39: 450.9 | Z39: 36 | AA39: 466.9 | AB39: 1571.5 | AC39: 12 | AE39: 202 Norte | AF39: 144 | AG39: 60 | AH39: 162 | AI39: 2059.5 | AJ39: 5 | AM39: 202 Norte | AN39: =D39+K39+R39+Y39+AF39 -> 1643.46 | AO39: =E39+L39+S39+Z39+AG39 -> 96 | AP39: =F39+M39+T39+AA39+AH39 -> 1756.46 | AQ39: =H39+O39+V39+AC39+AJ39 -> 60
C40: 213 / Sof | J40: 213 Norte | Q40: 213 Norte | X40: 213 Norte | AE40: 213 Norte | AM40: 213 Norte | AN40: =D40+K40+R40+Y40+AF40 -> 0 | AO40: =E40+L40+S40+Z40+AG40 -> 0 | AP40: =F40+M40+T40+AA40+AH40 -> 0 | AQ40: =H40+O40+V40+AC40+AJ40 -> 0
...

Sheet Faturamento 
J1: Vendas no Sistema 2023
I2: Lojas | J2: Setembro | K2: Outubro | L2: Novembro | M2: Dezembro
I3: 202 | J3: 14688.94 | K3: 16995.73 | L3: 13920.6 | M3: 9776.45
I4: 213 | J4: 17401.26 | K4: 17473.56 | L4: 14995.9 | M4: 17427.74
I5: 307 | J5: 39820.56 | K5: 41926.9 | L5: 37635.21 | M5: 38715.8
I6: 313 | J6: 0 | K6: 7543 | L6: 13055.9 | M6: 10273.45
I7: Lago | L7: 4075.53 | M7: 8989.87
I8: Sudoeste | J8: 24877.16 | K8: 17318.11 | L8: 19683.3 | M8: 17992.5
I9: Total: | J9: =J3+J4+J5+J6+J7+J8 -> 96787.92 | K9: =K3+K4+K5+K6+K7+K8 -> 101257.3 | L9: =L3+L4+L5+L6+L7+L8 -> 103366.44 | M9: =M3+M4+M5+M6+M7+M8 -> 103175.81
I10: Total Ano: | J10: =J9+K9+L9+M9 -> 404587.47
B12: Vendas no Sistema 2024
A13: Lojas | B13: Janeiro | C13: Fevereiro | D13: Março | E13: Abril | F13: Maio | G13: Junho | H13: Julho | I13: Agosto | J13: Setembro | K13: Outubro | L13: Novembro | M13: Dezembro | O13: Média do ano
A14: 202 Norte | B14: 11957.8 | C14: 9855.58 | D14: 11843.23 | E14: 13074.46 | F14: 11484.73 | G14: 13540.53 | H14: 17314.1 | I14: 17483.18 | J14: 15424.26 | K14: 13337.64 | L14: 16819.49 | M14: 14128.32 | O14: =(C14+D14+E14+F14+G14+H14+I14+J14+K14+L14+M14)/12 -> 12858.793
A15: 213 Norte | B15: 18085.15 | C15: 16018.83 | D15: 14639.95 | E15: 16569.81 | F15: 18127.68 | G15: 16896.93 | H15: 17790.89 | I15: 19754.73 | J15: 17001.54 | K15: 17803.02 | L15: 13036.38 | M15: 17726.84 | O15: =(C15+D15+E15+F15+G15+H15+I15+J15+K15+L15+M15)/12 -> 15447.217
A16: 307 Norte | B16: 40832.92 | C16: 34766.15 | D16: 37138.31 | E16: 36583.9 | F16: 35900.67 | G16: 32882.06 | H16: 40662.58 | I16: 39584.16 | J16: 37348.14 | K16: 43194.11 | L16: 39268.88 | M16: 40693.26 | O16: =(C16+D16+E16+F16+G16+H16+I16+J16+K16+L16+M16)/12 -> 34835.185
A17: 313 Norte | B17: 9680.39 | C17: 11122.08 | D17: 12643.38 | E17: 13284.78 | F17: 12605.04 | G17: 13112.08 | H17: 14477.14 | I17: 12789.4 | J17: 14418.09 | K17: 11108.22 | L17: 14684.53 | M17: 13726.15 | O17: =(C17+D17+E17+F17+G17+H17+I17+J17+K17+L17+M17)/12 -> 11997.574
A18: 314 Sul | I18: 4456.43 | J18: 8695.66 | K18: 12076.09 | L18: 11549.62 | M18: 9387.9 | O18: =(C18+D18+E18+F18+G18+H18+I18+J18+K18+L18+M18)/5 -> 9233.14
A19: Lago Norte | B19: 12000.82 | C19: 9407.74 | D19: 12603.58 | E19: 12708.46 | F19: 18034.45 | G19: 16798.24 | H19: 16481.65 | I19: 18241.19 | J19: 16195.89 | K19: 18783.68 | L19: 20264.86 | M19: 15775.31 | O19: =(C19+D19+E19+F19+G19+H19+I19+J19+K19+L19+M19)/12 -> 14607.921
A20: Sudoeste | B20: 21809.85 | C20: 19266.65 | D20: 16581.98 | E20: 14334.25 | F20: 17403.8 | G20: 19475.73 | H20: 22992.38 | I20: 19444.64 | J20: 15245.15 | K20: 18224.85 | L20: 16608.49 | M20: 18105.8 | O20: =(C20+D20+E20+F20+G20+H20+I20+J20+K20+L20+M20)/12 -> 16473.643
A21: Noroeste | D21: 21353.58 | E21: 30809.12 | F21: 35437.47 | G21: 48159.72 | H21: 55238.9 | I21: 53474.74 | J21: 53145.15 | K21: 57749.37 | L21: 49235.12 | M21: 47041.73 | O21: =(C21+D21+E21+F21+G21+H21+I21+J21+K21+L21+M21)/10 -> 45164.49
A22: Total Mês | B22: =B14+B15+B16+B17+B18+B19+B20+B21 -> 114366.93 | C22: =C14+C15+C16+C17+C18+C19+C20+C21 -> 100437.03 | D22: =D14+D15+D16+D17+D18+D19+D20+D21 -> 126804.01 | E22: =E14+E15+E16+E17+E18+E19+E20+E21 -> 137364.78 | F22: =F14+F15+F16+F17+F18+F19+F20+F21 -> 148993.84 | G22: =G14+G15+G16+G17+G18+G19+G20+G21 -> 160865.29 | H22: =H14+H15+H16+H17+H18+H19+H20+H21 -> 184957.64 | I22: =I14+I15+I16+I17+I18+I19+I20+I21 -> 185228.47 | ... M22: =M14+M15+M16+M17+M18+M19+M20+M21 -> 176585.31 | O22: =(C22+D22+E22+F22+G22+H22+I22+J22+K22+L22+M22)/12 -> 147704.55
A23: Total Ano: | B23: =B22+C22+D22+E22+F22+G22+H22+I22+J22+K22+L22+M22 -> 1886821.5
B25: Vendas no Sistema 2025
A26: Lojas | B26: Janeiro | C26: Fevereiro | D26: Março | E26: Abril | F26: Maio | G26: Junho | H26: Julho | I26: Agosto | J26: Setembro | K26: Outubro | L26: Novembro | M26: Dezembro
A27: 202 Norte | B27: 18140.59 | C27: 15528.37 | D27: 15073.15 | E27: 15135.61 | F27: 19623.04 | G27: 18366.98 | H27: 21472.85 | I27: 17722.95 | J27: 19589.33 | K27: 18448.43 | L27: 17093.15 | M27: 12555.4 | O27: 20000
A28: 213 Norte | B28: 16491.46 | C28: 12876.86 | D28: 16473.35 | E28: 5346.9 | F28: 23.4 | G28: 0 | H28: 266.9 | I28: 233 | J28: 110 | K28: 682.8 | L28: 360 | M28: 54.9
A29: 307 Norte | B29: 43525.27 | C29: 33837.39 | D29: 34965.59 | E29: 38467.01 | F29: 47263.05 | G29: 38706.32 | H29: 44217.01 | I29: 42862.3 | J29: 44423.08 | K29: 44606.51 | L29: 38493.02 | M29: 44165.31 | O29: 44000
A30: 313 Norte | B30: 21962.36 | C30: 12537.45 | D30: 19666.08 | E30: 21202.74 | F30: 29454.83 | G30: 26999.2 | H30: 26380.18 | I30: 27309.15 | J30: 26091.28 | K30: 25097.95 | L30: 21978.9 | M30: 21777.68 | O30: 28000
A31: 314 Sul | B31: 15848.95 | C31: 8847.69 | D31: 13651.71 | E31: 15100.58 | F31: 15504.5 | G31: 17680.89 | H31: 13408.4 | I31: 16213 | J31: 15156.9 | K31: 13950.8 | L31: 10917.25 | M31: 5809.86
A32: Lago Norte | B32: 17360.97 | C32: 16812.79 | D32: 16366.79 | E32: 17614.19 | F32: 22195.55 | G32: 22858.11 | H32: 23633.26 | I32: 18961.82 | J32: 23331.76 | K32: 21151.72 | L32: 16791.69 | M32: 18192.62 | O32: 23000
A33: Sudoeste | B33: 21302.49 | C33: 15823.85 | D33: 19665.84 | E33: 20658.61 | F33: 18943.27 | G33: 19884.67 | H33: 18736.87 | I33: 19783.77 | J33: 21980.55 | K33: 18246.38 | L33: 14083.21 | M33: 17840.81 | O33: 21000
A34: Noroeste | B34: 62860.36 | C34: 48283.62 | D34: 56924.27 | E34: 59868.86 | F34: 64708.01 | G34: 55012.69 | H34: 71350.15 | I34: 57628.49 | J34: 64575.91 | K34: 54630.2 | L34: 59398.06 | M34: 55236.21 | O34: 64000
A35: Total Mês | B35: =B27+B28+B29+B30+B31+B32+B33+B34 -> 217492.45 | C35: =C27+C28+C29+C30+C31+C32+C33+C34 -> 164548.02 | D35: =D27+D28+D29+D30+D31+D32+D33+D34 -> 192786.78 | E35: =E27+E28+E29+E30+E31+E32+E33+E34 -> 193394.5 | F35: =F27+F28+F29+F30+F31+F32+F33+F34 -> 217715.65 | G35: =G27+G28+G29+G30+G31+G32+G33+G34 -> 199508.86 | H35: =H27+H28+H29+H30+H31+H32+H33+H34 -> 219465.62 | I35: =I27+I28+I29+I30+I31+I32+I33+I34 -> 200714.48 | ... M35: =M27+M28+M29+M30+M31+M32+M33+M34 -> 175632.79 | O35: =O27+O28+O29+O30+O31+O32+O33+O34 -> 200000
A36: Total Ano: | B36: =B35+C35+D35+E35+F35+G35+H35+I35+J35+K35+L35+M35 -> 2372448
B38: Vendas no Sistema 2026
A39: Lojas | B39: Janeiro | C39: Fevereiro | D39: Março | E39: Abril | F39: Maio | G39: Junho | H39: Julho | I39: Agosto | J39: Setembro | K39: Outubro | L39: Novembro | M39: Dezembro
A40: 202 Norte | B40: =Jan!D128 -> 14956.86 | C40: =Fev!D128 -> 15394.71 | D40: =Mar!D128 -> 0 | E40: =Abr!D128 -> 0 | F40: =Mai!D128 -> 0 | G40: =Jun!D128 -> 0 | H40: =Jul!D128 -> 0 | I40: =Ago!D128 -> 0 | J40: =Set!D128 -> 0 | K40: =Out!D128 -> 0 | L40: =Nov!D128 -> 0 | M40: =Dez!D128 -> 0 | O40: 20000
A41: 213 Norte / SOF | B41: =Jan!D129 -> 0 | C41: =Fev!D129 -> 0 | D41: =Mar!D129 -> 0 | E41: =Abr!D129 -> 0 | F41: =Mai!D129 -> 0 | G41: =Jun!D129 -> 0 | H41: =Jul!D129 -> 0 | I41: =Ago!D129 -> 0 | J41: =Set!D129 -> 0 | K41: =Out!D129 -> 0 | L41: =Nov!D129 -> 0 | M41: =Dez!D129 -> 0
A42: 307 Norte | B42: =Jan!D130 -> 48020.92 | C42: =Fev!D130 -> 32756.95 | D42: =Mar!D130 -> 0 | E42: =Abr!D130 -> 0 | F42: =Mai!D130 -> 0 | G42: =Jun!D130 -> 0 | H42: =Jul!D130 -> 0 | I42: =Ago!D130 -> 0 | J42: =Set!D130 -> 0 | K42: =Out!D130 -> 0 | L42: =Nov!D130 -> 0 | M42: =Dez!D130 -> 0 | O42: 44000
A43: 313 Norte | B43: =Jan!D131 -> 30515.35 | C43: =Fev!D131 -> 18490.14 | D43: =Mar!D131 -> 0 | E43: =Abr!D131 -> 0 | F43: =Mai!D131 -> 0 | G43: =Jun!D131 -> 0 | H43: =Jul!D131 -> 0 | I43: =Ago!D131 -> 0 | J43: =Set!D131 -> 0 | K43: =Out!D131 -> 0 | L43: =Nov!D131 -> 0 | M43: =Dez!D131 -> 0 | O43: 28000
...

Sheet Fev
B1: Dia | C1: Lojas | D1: Faturamento dia | E1: Não pago dia | F1: Recebido dia | G1: Não pago Acumulado | H1: Peças | I1: Dia | J1: Lojas | K1: Faturamento | L1: Não pago dia | M1: Recebido dia | N1: Não pago Acumulado | O1: Peças | P1: Dia | Q1: Lojas | R1: Faturamento | S1: Não pago dia | T1: Recebido dia | U1: Não pago Acumulado | V1: Peças | W1: Dia | X1: Lojas | Y1: Faturamento | Z1: Não pago dia | AA1: Recebido dia | AB1: Não pago Acumulado | AC1: Peças | AD1: Dia | AE1: Lojas | AF1: Faturamento | AG1: Não pago dia | AH1: Recebido dia | AI1: Não pago Acumulado | AJ1: Peças | AM1: Lojas | AN1: Faturamento | AO1: Não pago dia | AP1: Recebido | AQ1: Peças
A2: Segunda-feira | C2: Lago Norte | I2: 46055 | J2: Lago Norte | K2: 358.6 | L2: 54.9 | M2: 430.7 | N2: 857 | O2: 33 | P2: 46062 | Q2: Lago Norte | R2: 474.91 | S2: 0 | T2: 474.91 | U2: 1661.4 | V2: 28 | W2: 46069 | X2: Lago Norte | Y2: 451.8 | Z2: 0 | AA2: 451.8 | AB2: 1876.4 | AC2: 18 | AD2: 46076 | AE2: Lago Norte | AF2: 611.61 | AG2: 232.87 | AH2: 433.64 | AI2: 1300.97 | AJ2: 43 | AL2: Faturamento Total das Segundas-feiras | AM2: Lago Norte | AN2: =D2+K2+R2+Y2+AF2 -> 1896.92 | AO2: =E2+L2+S2+Z2+AG2 -> 287.77 | AP2: =F2+M2+T2+AA2+AH2 -> 1791.05 | AQ2: =H2+O2+V2+AC2+AJ2 -> 122
C3: 202 Norte | J3: 202 Norte | K3: 417 | L3: 0 | M3: 517 | N3: 2407.4 | O3: 13 | Q3: 202 Norte | R3: 170 | S3: 45 | T3: 125 | U3: 920.6 | V3: 39 | X3: 202 Norte | Y3: 214 | Z3: 0 | AA3: 480 | AB3: 1177.4 | AC3: 11 | AE3: 202 Norte | AF3: 395.9 | AG3: 305.9 | AH3: 135 | AI3: 2326.1 | AJ3: 17 | AM3: 202 Norte | AN3: =D3+K3+R3+Y3+AF3 -> 1196.9 | AO3: =E3+L3+S3+Z3+AG3 -> 350.9 | AP3: =F3+M3+T3+AA3+AH3 -> 1257 | AQ3: =H3+O3+V3+AC3+AJ3 -> 80
C4: 213 Norte | J4: 213 Norte | Q4: 213 Norte | X4: 213 Norte | AE4: 213 Norte | AM4: 213 Norte | AN4: =D4+K4+R4+Y4+AF4 -> 0 | AO4: =E4+L4+S4+Z4+AG4 -> 0 | AP4: =F4+M4+T4+AA4+AH4 -> 0 | AQ4: =H4+O4+V4+AC4+AJ4 -> 0
C5: 307 Norte | J5: 307 Norte | K5: 2695.4 | L5: 752 | M5: 2115.4 | N5: 5889.43 | O5: 100 | Q5: 307 Norte | R5: 3038 | S5: 853 | T5: 2970.08 | U5: 5906.96 | V5: 150 | X5: 307 Norte | Y5: 1102.7 | Z5: 186.9 | AA5: 1289.91 | AB5: 5087.45 | AC5: 47 | AE5: 307 Norte | AF5: 694.8 | AG5: 132.9 | AH5: 651.9 | AI5: 5474.51 | AJ5: 23 | AM5: 307 Norte | AN5: =D5+K5+R5+Y5+AF5 -> 7530.9 | AO5: =E5+L5+S5+Z5+AG5 -> 1924.8 | AP5: =F5+M5+T5+AA5+AH5 -> 7027.29 | AQ5: =H5+O5+V5+AC5+AJ5 -> 320
C6: 313 Norte | J6: 313 Norte | K6: =3947.6-2664 -> 1283.6 | L6: 0 | M6: 1363.6 | N6: =4623.35-2664 -> 1959.35 | O6: =162-75 -> 87 | Q6: 313 Norte | R6: 962.9 | S6: 60 | T6: 902.9 | U6: 1562.6 | V6: 43 | X6: 313 Norte | Y6: 407.9 | Z6: 0 | AA6: 407.9 | AB6: 1533.6 | AC6: 28 | AE6: 313 Norte | AF6: 1463.3 | AG6: 423 | AH6: 1040.3 | AI6: 1942.1 | AJ6: 57 | AM6: 313 Norte | AN6: =D6+K6+R6+Y6+AF6 -> 4117.7 | AO6: =E6+L6+S6+Z6+AG6 -> 483 | AP6: =F6+M6+T6+AA6+AH6 -> 3714.7 | AQ6: =H6+O6+V6+AC6+AJ6 -> 215
C7: 314 Sul | J7: 314 Sul | Q7: 314 Sul | X7: 314 Sul | AE7: 314 Sul | AM7: 314 Sul | AN7: =D7+K7+R7+Y7+AF7 -> 0 | AO7: =E7+L7+S7+Z7+AG7 -> 0 | AP7: =F7+M7+T7+AA7+AH7 -> 0 | AQ7: =H7+O7+V7+AC7+AJ7 -> 0
C8: Sudoeste | J8: Sudoeste | K8: 817 | L8: 42 | M8: 1051 | N8: 2242.29 | O8: 42 | Q8: Sudoeste | R8: 314.9 | S8: 54.9 | T8: 676.9 | U8: 2066.79 | V8: 25 | X8: Sudoeste | AE8: Sudoeste | AF8: 807.8 | AG8: 807.8 | AH8: 113.35 | AI8: 2703.24 | AJ8: 46 | AM8: Sudoeste | AN8: =D8+K8+R8+Y8+AF8 -> 1939.7 | AO8: =E8+L8+S8+Z8+AG8 -> 904.7 | AP8: =F8+M8+T8+AA8+AH8 -> 1841.25 | AQ8: =H8+O8+V8+AC8+AJ8 -> 113
C9: Noroeste | J9: Noroeste | K9: 2308.7 | L9: 0 | M9: 2843.6 | N9: 6485.54 | O9: 139 | Q9: Noroeste | R9: 4599 | S9: 711 | T9: 3906 | U9: 7330.24 | V9: 195 | X9: Noroeste | Y9: 898.6 | Z9: 164.7 | AA9: 922.9 | AB9: 7214.64 | AC9: 37 | AE9: Noroeste | AF9: 3714.34 | AG9: 776.4 | AH9: 3119.22 | AI9: 7950.16 | AJ9: 138 | AM9: Noroeste | AN9: =D9+K9+R9+Y9+AF9 -> 11520.64 | AO9: =E9+L9+S9+Z9+AG9 -> 1652.1 | AP9: =F9+M9+T9+AA9+AH9 -> 10791.72 | AQ9: =H9+O9+V9+AC9+AJ9 -> 509
C10: Total: | D10: =D2+D3+D4+D5+D6+D7+D8+D9 -> 0 | E10: =E2+E3+E4+E5+E6+E7+E8+E9 -> 0 | F10: =F2+F3+F4+F5+F6+F7+F8+F9 -> 0 | G10: =G2+G3+G4+G5+G6+G7+G8+G9 -> 0 | H10: =H2+H3+H4+H5+H6+H7+H8+H9 -> 0 | J10: Total: | K10: =K2+K3+K4+K5+K6+K7+K8+K9 -> 7880.3 | L10: =L2+L3+L4+L5+L6+L7+L8+L9 -> 848.9 | M10: =M2+M3+M4+M5+M6+M7+M8+M9 -> 8321.3 | N10: =N2+N3+N4+N5+N6+N7+N8+N9 -> 19841.01 | O10: =O2+O3+O4+O5+O6+O7+O8+O9 -> 414 | Q10: Total: | R10: =R2+R3+R4+R5+R6+R7+R8+R9 -> 9559.71 | S10: =S2+S3+S4+S5+S6+S7+S8+S9 -> 1723.9 | T10: =T2+T3+T4+T5+T6+T7+T8+T9 -> 9055.79 | U10: =U2+U3+U4+U5+U6+U7+U8+U9 -> 19448.59 | V10: =V2+V3+V4+V5+V6+V7+V8+V9 -> 480 | X10: Total: | Y10: =Y2+Y3+Y4+Y5+Y6+Y7+Y8+Y9 -> 3075 | Z10: =Z2+Z3+Z4+Z5+Z6+Z7+Z8+Z9 -> 351.6 | AA10: =AA2+AA3+AA4+AA5+AA6+AA7+AA8+AA9 -> 3552.51 | AB10: =AB2+AB3+AB4+AB5+AB6+AB7+AB8+AB9 -> 16889.49 | AC10: =AC2+AC3+AC4+AC5+AC6+AC7+AC8+AC9 -> 141 | AE10: Total: | AF10: =AF2+AF3+AF4+AF5+AF6+AF7+AF8+AF9 -> 7687.75 | AG10: =AG2+AG3+AG4+AG5+AG6+AG7+AG8+AG9 -> 2678.87 | AH10: =AH2+AH3+AH4+AH5+AH6+AH7+AH8+AH9 -> 5493.41 | AI10: =AI2+AI3+AI4+AI5+AI6+AI7+AI8+AI9 -> 21697.08 | AJ10: =AJ2+AJ3+AJ4+AJ5+AJ6+AJ7+AJ8+AJ9 -> 324 | AM10: Total: | AN10: =AN2+AN3+AN4+AN5+AN6+AN7+AN8+AN9 -> 28202.76 | AO10: =AO2+AO3+AO4+AO5+AO6+AO7+AO8+AO9 -> 5603.27 | AP10: =AP2+AP3+AP4+AP5+AP6+AP7+AP8+AP9 -> 26423.01 | AQ10: =AQ2+AQ3+AQ4+AQ5+AQ6+AQ7+AQ8+AQ9 -> 1359
C11: Faturado dia real | D11: =D10-E10 -> 0 | J11: Faturado dia real | K11: =K10-L10 -> 7031.4 | Q11: Faturado dia real | R11: =R10-S10 -> 7835.81 | X11: Faturado dia real | Y11: =Y10-Z10 -> 2723.4 | AE11: Faturado dia real | AF11: =AF10-AG10 -> 5008.88 | AM11: Fat. Real | AN11: =AN10-AO10 -> 22599.49
C12: Recebido dia real | D12: =F10-E10 -> 0 | J12: Recebido dia real | K12: =M10-L10 -> 7472.4 | Q12: Recebido dia real | R12: =T10-S10 -> 7331.89 | X12: Recebido dia real | Y12: =AA10-Z10 -> 3200.91 | AE12: Recebido dia real | AF12: =AH10-AG10 -> 2814.54
B13: Dia | C13: Lojas | D13: Faturamento dia | E13: Não pago dia | F13: Recebido dia | G13: Não pago Acumulado | H13: Peças | I13: Dia | J13: Lojas | K13: Faturamento | L13: Não pago dia | M13: Recebido dia | N13: Não pago Acumulado | O13: Peças | P13: Dia | Q13: Lojas | R13: Faturamento | S13: Não pago dia | T13: Recebido dia | U13: Não pago Acumulado | V13: Peças | W13: Dia | X13: Lojas | Y13: Faturamento | Z13: Não pago dia | AA13: Recebido dia | AB13: Não pago Acumulado | AC13: Peças | AD13: Dia | AE13: Lojas | AF13: Faturamento | AG13: Não pago dia | AH13: Recebido dia | AI13: Não pago Acumulado | AJ13: Peças | AM13: Lojas | AN13: Faturamento | AO13: Não pago dia | AP13: Recebido | AQ13: Peças
A14: Terça-feira | C14: Lago Norte | I14: 46056 | J14: Lago Norte | K14: 573.8 | L14: 30 | M14: 704.8 | N14: 726 | O14: 19 | P14: 46063 | Q14: Lago Norte | R14: 951.5 | S14: 190 | T14: 761.5 | U14: 1851.4 | V14: 35 | W14: 46070 | X14: Lago Norte | AD14: 46077 | AE14: Lago Norte | AF14: 890.7 | AG14: 0 | AH14: 975.7 | AI14: 1215.97 | AJ14: 40 | AL14: Faturamento Total das Terças-feiras | AM14: Lago Norte | AN14: =D14+K14+R14+Y14+AF14 -> 2416 | AO14: =E14+L14+S14+Z14+AG14 -> 220 | AP14: =F14+M14+T14+AA14+AH14 -> 2442 | AQ14: =H14+O14+V14+AC14+AJ14 -> 94
C15: 202 Norte | J15: 202 Norte | K15: 90.2 | L15: 30 | M15: 120.2 | N15: 2377.4 | O15: 15 | Q15: 202 Norte | R15: 927 | S15: 406 | T15: 575 | U15: 1272.6 | V15: 45 | X15: 202 Norte | AE15: 202 Norte | AF15: 447.3 | AG15: 329.4 | AH15: 117.9 | AI15: 2655.5 | AJ15: 21 | AM15: 202 Norte | AN15: =D15+K15+R15+Y15+AF15 -> 1464.5 | AO15: =E15+L15+S15+Z15+AG15 -> 765.4 | AP15: =F15+M15+T15+AA15+AH15 -> 813.1 | AQ15: =H15+O15+V15+AC15+AJ15 -> 81
C16: 213 Norte | J16: 213 Norte | Q16: 213 Norte | X16: 213 Norte | AE16: 213 Norte | AM16: 213 Norte | AN16: =D16+K16+R16+Y16+AF16 -> 0 | AO16: =E16+L16+S16+Z16+AG16 -> 0 | AP16: =F16+M16+T16+AA16+AH16 -> 0 | AQ16: =H16+O16+V16+AC16+AJ16 -> 0
C17: 307 Norte | J17: 307 Norte | K17: 2241.63 | L17: 55.33 | M17: 2365.3 | N17: 5765.76 | O17: 93 | Q17: 307 Norte | R17: 1353.8 | S17: 75 | T17: 1594.2 | U17: 5659.96 | V17: 73 | X17: 307 Norte | AE17: 307 Norte | AF17: 1505.9 | AG17: 80 | AH17: 1473.9 | AI17: 5506.51 | AJ17: 90 | AM17: 307 Norte | AN17: =D17+K17+R17+Y17+AF17 -> 5101.33 | AO17: =E17+L17+S17+Z17+AG17 -> 210.33 | AP17: =F17+M17+T17+AA17+AH17 -> 5433.4 | AQ17: =H17+O17+V17+AC17+AJ17 -> 256
C18: 313 Norte | J18: 313 Norte | K18: 687 | L18: 80 | M18: 1234.55 | N18: =4075.8-2664 -> 1411.8 | O18: 46 | Q18: 313 Norte | R18: 873 | S18: 249 | T18: 734 | U18: 1701.6 | V18: 39 | X18: 313 Norte | AE18: 313 Norte | AF18: 707.9 | AG18: 0 | AH18: 707.9 | AI18: 1942.1 | AJ18: 29 | AM18: 313 Norte | AN18: =D18+K18+R18+Y18+AF18 -> 2267.9 | AO18: =E18+L18+S18+Z18+AG18 -> 329 | AP18: =F18+M18+T18+AA18+AH18 -> 2676.45 | AQ18: =H18+O18+V18+AC18+AJ18 -> 114
C19: 314 Sul | J19: 314 Sul | Q19: 314 Sul | X19: 314 Sul | AE19: 314 Sul | AM19: 314 Sul | AN19: =D19+K19+R19+Y19+AF19 -> 0 | AO19: =E19+L19+S19+Z19+AG19 -> 0 | AP19: =F19+M19+T19+AA19+AH19 -> 0 | AQ19: =H19+O19+V19+AC19+AJ19 -> 0
C20: Sudoeste | J20: Sudoeste | K20: 441.04 | L20: 0 | M20: 476.04 | N20: 2207.29 | O20: 23 | Q20: Sudoeste | R20: 163.9 | S20: 0 | T20: 213.9 | U20: 2016.79 | V20: 11 | X20: Sudoeste | AE20: Sudoeste | AF20: 926 | AG20: 0 | AH20: 1203 | AI20: 2426.24 | AJ20: 25 | AM20: Sudoeste | AN20: =D20+K20+R20+Y20+AF20 -> 1530.94 | AO20: =E20+L20+S20+Z20+AG20 -> 0 | AP20: =F20+M20+T20+AA20+AH20 -> 1892.94 | AQ20: =H20+O20+V20+AC20+AJ20 -> 59
C21: Noroeste | J21: Noroeste | K21: 992.7 | L21: 328.9 | M21: 728.8 | N21: 6749.44 | O21: 53 | Q21: Noroeste | R21: 2034.7 | S21: 68 | T21: 2020.7 | U21: 7344.24 | V21: 139 | X21: Noroeste | AE21: Noroeste | AF21: 1434.4 | AG21: 276 | AH21: 1538.3 | AI21: 7660.26 | AJ21: 90 | AM21: Noroeste | AN21: =D21+K21+R21+Y21+AF21 -> 4461.8 | AO21: =E21+L21+S21+Z21+AG21 -> 672.9 | AP21: =F21+M21+T21+AA21+AH21 -> 4287.8 | AQ21: =H21+O21+V21+AC21+AJ21 -> 282
C22: Total: | D22: =D14+D15+D16+D17+D18+D19+D20+D21 -> 0 | E22: =E14+E15+E16+E17+E18+E19+E20+E21 -> 0 | F22: =F14+F15+F16+F17+F18+F19+F20+F21 -> 0 | G22: =G14+G15+G16+G17+G18+G19+G20+G21 -> 0 | H22: =H14+H15+H16+H17+H18+H19+H20+H21 -> 0 | J22: Total: | K22: =K14+K15+K16+K17+K18+K19+K20+K21 -> 5026.37 | L22: =L14+L15+L16+L17+L18+L19+L20+L21 -> 524.23 | M22: =M14+M15+M16+M17+M18+M19+M20+M21 -> 5629.69 | N22: =N14+N15+N16+N17+N18+N19+N20+N21 -> 19237.69 | O22: =O14+O15+O16+O17+O18+O19+O20+O21 -> 249 | Q22: Total: | R22: =R14+R15+R16+R17+R18+R19+R20+R21 -> 6303.9 | S22: =S14+S15+S16+S17+S18+S19+S20+S21 -> 988 | T22: =T14+T15+T16+T17+T18+T19+T20+T21 -> 5899.3 | U22: =U14+U15+U16+U17+U18+U19+U20+U21 -> 19846.59 | V22: =V14+V15+V16+V17+V18+V19+V20+V21 -> 342 | X22: Total: | Y22: =Y14+Y15+Y16+Y17+Y18+Y19+Y20+Y21 -> 0 | Z22: =Z14+Z15+Z16+Z17+Z18+Z19+Z20+Z21 -> 0 | AA22: =AA14+AA15+AA16+AA17+AA18+AA19+AA20+AA21 -> 0 | AB22: =AB14+AB15+AB16+AB17+AB18+AB19+AB20+AB21 -> 0 | AC22: =AC14+AC15+AC16+AC17+AC18+AC19+AC20+AC21 -> 0 | AE22: Total: | AF22: =AF14+AF15+AF16+AF17+AF18+AF19+AF20+AF21 -> 5912.2 | AG22: =AG14+AG15+AG16+AG17+AG18+AG19+AG20+AG21 -> 685.4 | AH22: =AH14+AH15+AH16+AH17+AH18+AH19+AH20+AH21 -> 6016.7 | AI22: =AI14+AI15+AI16+AI17+AI18+AI19+AI20+AI21 -> 21406.58 | AJ22: =AJ14+AJ15+AJ16+AJ17+AJ18+AJ19+AJ20+AJ21 -> 295 | AM22: Total: | AN22: =AN14+AN15+AN16+AN17+AN18+AN19+AN20+AN21 -> 17242.47 | AO22: =AO14+AO15+AO16+AO17+AO18+AO19+AO20+AO21 -> 2197.63 | AP22: =AP14+AP15+AP16+AP17+AP18+AP19+AP20+AP21 -> 17545.69 | AQ22: =AQ14+AQ15+AQ16+AQ17+AQ18+AQ19+AQ20+AQ21 -> 886
C23: Faturado dia real | D23: =D22-E22 -> 0 | J23: Faturado dia real | K23: =K22-L22 -> 4502.14 | Q23: Faturado dia real | R23: =R22-S22 -> 5315.9 | X23: Faturado dia real | Y23: =Y22-Z22 -> 0 | AE23: Faturado dia real | AF23: =AF22-AG22 -> 5226.8 | AM23: Fat. Real | AN23: =AN22-AO22 -> 15044.84
C24: Recebido dia real | D24: =F22-E22 -> 0 | J24: Recebido dia real | K24: =M22-L22 -> 5105.46 | Q24: Recebido dia real | R24: =T22-S22 -> 4911.3 | X24: Recebido dia real | Y24: =AA22-Z22 -> 0 | AE24: Recebido dia real | AF24: =AH22-AG22 -> 5331.3
B25: Dia | C25: Lojas | D25: Faturamento dia | E25: Não pago dia | F25: Recebido dia | G25: Não pago Acumulado | H25: Peças | I25: Dia | J25: Lojas | K25: Faturamento | L25: Não pago dia | M25: Recebido dia | N25: Não pago Acumulado | O25: Peças | P25: Dia | Q25: Lojas | R25: Faturamento | S25: Não pago dia | T25: Recebido dia | U25: Não pago Acumulado | V25: Peças | W25: Dia | X25: Lojas | Y25: Faturamento | Z25: Não pago dia | AA25: Recebido dia | AB25: Não pago Acumulado | AC25: Peças | AD25: Dia | AE25: Lojas | AF25: Faturamento | AG25: Não pago dia | AH25: Recebido dia | AI25: Não pago Acumulado | AJ25: Peças | AM25: Lojas | AN25: Faturamento | AO25: Não pago dia | AP25: Recebido | AQ25: Peças
A26: Quarta-feira | C26: Lago Norte | I26: 46057 | J26: Lago Norte | K26: 913 | L26: 75 | M26: 838 | N26: 801 | O26: 38 | P26: 46064 | Q26: Lago Norte | R26: 1026 | S26: 0 | T26: 1056 | U26: 1821.4 | V26: 29 | W26: 46071 | X26: Lago Norte | Y26: 996.5 | Z26: 105 | AA26: 1857.1 | AB26: 1015.8 | AC26: 14 | AD26: 46078 | AE26: Lago Norte | AF26: 1136 | AG26: 60 | AH26: 1876 | AI26: 1275.97 | AJ26: 56 | AL26: Faturamento Total das Quartas-feiras | AM26: Lago Norte | AN26: =D26+K26+R26+Y26+AF26 -> 4071.5 | AO26: =E26+L26+S26+Z26+AG26 -> 240 | AP26: =F26+M26+T26+AA26+AH26 -> 5627.1 | AQ26: =H26+O26+V26+AC26+AJ26 -> 137
C27: 202 Norte | J27: 202 Norte | K27: 623.6 | L27: 36 | M27: 587.6 | N27: 2413.4 | O27: 33 | Q27: 202 Norte | R27: 611.8 | S27: 91.9 | T27: 519.9 | U27: 1364.5 | V27: 28 | X27: 202 Norte | Y27: 198 | Z27: 0 | AA27: 250 | AB27: 1125.4 | AC27: 16 | AE27: 202 Norte | AF27: 654.62 | AG27: 473.62 | AH27: 181 | AI27: 3129.12 | AJ27: 20 | AM27: 202 Norte | AN27: =D27+K27+R27+Y27+AF27 -> 2088.02 | AO27: =E27+L27+S27+Z27+AG27 -> 601.52 | AP27: =F27+M27+T27+AA27+AH27 -> 1538.5 | AQ27: =H27+O27+V27+AC27+AJ27 -> 97
C28: 213 Norte | J28: 213 Norte | Q28: 213 Norte | X28: 213 Norte | AE28: 213 Norte | AM28: 213 Norte | AN28: =D28+K28+R28+Y28+AF28 -> 0 | AO28: =E28+L28+S28+Z28+AG28 -> 0 | AP28: =F28+M28+T28+AA28+AH28 -> 0 | AQ28: =H28+O28+V28+AC28+AJ28 -> 0
C29: 307 Norte | J29: 307 Norte | K29: 1985 | L29: 303.8 | M29: 2389 | N29: 5361.76 | O29: 83 | Q29: 307 Norte | R29: 923.4 | S29: 265.5 | T29: 966.8 | U29: 5616.56 | V29: 39 | X29: 307 Norte | Y29: 888.4 | Z29: 65 | AA29: 823.48 | AB29: 5152.45 | AC29: 53 | AE29: 307 Norte | AF29: 2519.7 | AG29: 1152.9 | AH29: 3099.08 | AI29: 4829.56 | AJ29: 55 | AM29: 307 Norte | AN29: =D29+K29+R29+Y29+AF29 -> 6316.5 | AO29: =E29+L29+S29+Z29+AG29 -> 1787.2 | AP29: =F29+M29+T29+AA29+AH29 -> 7278.36 | AQ29: =H29+O29+V29+AC29+AJ29 -> 230
C30: 313 Norte | J30: 313 Norte | K30: 840 | L30: 0 | M30: 920 | N30: =3995.8-2664 -> 1331.8 | O30: 28 | Q30: 313 Norte | R30: 408 | S30: 135 | T30: 582 | U30: 1527.6 | V30: 21 | X30: 313 Norte | Y30: 91 | Z30: 0 | AA30: 145.9 | AB30: 1478.7 | AC30: 6 | AE30: 313 Norte | AF30: 795 | AG30: 46 | AH30: 1174 | AI30: 1563.1 | AJ30: 88 | AM30: 313 Norte | AN30: =D30+K30+R30+Y30+AF30 -> 2134 | AO30: =E30+L30+S30+Z30+AG30 -> 181 | AP30: =F30+M30+T30+AA30+AH30 -> 2821.9 | AQ30: =H30+O30+V30+AC30+AJ30 -> 143
C31: 314 Sul | J31: 314 Sul | Q31: 314 Sul | X31: 314 Sul | AE31: 314 Sul | AM31: 314 Sul | AN31: =D31+K31+R31+Y31+AF31 -> 0 | AO31: =E31+L31+S31+Z31+AG31 -> 0 | AP31: =F31+M31+T31+AA31+AH31 -> 0 | AQ31: =H31+O31+V31+AC31+AJ31 -> 0
C32: Sudoeste | J32: Sudoeste | K32: 1112.9 | L32: 494.9 | M32: 1208.4 | N32: 2111.79 | O32: 52 | Q32: Sudoeste | R32: 178.9 | S32: 74 | T32: 104.9 | U32: 2090.79 | V32: 12 | X32: Sudoeste | Y32: 727.7 | Z32: 0 | AA32: 727.7 | AB32: 2228.89 | AC32: 43 | AE32: Sudoeste | AF32: 239.8 | AG32: 0 | AH32: 688.6 | AI32: 1977.44 | AJ32: 8 | AM32: Sudoeste | AN32: =D32+K32+R32+Y32+AF32 -> 2259.3 | AO32: =E32+L32+S32+Z32+AG32 -> 568.9 | AP32: =F32+M32+T32+AA32+AH32 -> 2729.6 | AQ32: =H32+O32+V32+AC32+AJ32 -> 115
C33: Noroeste | J33: Noroeste | K33: 1101.01 | L33: 177.9 | M33: 1229.01 | N33: 6621.44 | O33: 57 | Q33: Noroeste | R33: 2079.4 | S33: 676.7 | T33: 1897.6 | U33: 7526.04 | V33: 98 | X33: Noroeste | Y33: 1530.4 | Z33: 187 | AA33: 1758 | AB33: 6987.04 | AC33: 82 | AE33: Noroeste | AF33: 2654.5 | AG33: 286.9 | AH33: 2721.6 | AI33: 7593.16 | AJ33: 93 | AM33: Noroeste | AN33: =D33+K33+R33+Y33+AF33 -> 7365.31 | AO33: =E33+L33+S33+Z33+AG33 -> 1328.5 | AP33: =F33+M33+T33+AA33+AH33 -> 7606.21 | AQ33: =H33+O33+V33+AC33+AJ33 -> 330
C34: Total: | D34: =D26+D27+D28+D29+D30+D31+D32+D33 -> 0 | E34: =E26+E27+E28+E29+E30+E31+E32+E33 -> 0 | F34: =F26+F27+F28+F29+F30+F31+F32+F33 -> 0 | G34: =G26+G27+G28+G29+G30+G31+G32+G33 -> 0 | H34: =H26+H27+H28+H29+H30+H31+H32+H33 -> 0 | J34: Total: | K34: =K26+K27+K28+K29+K30+K31+K32+K33 -> 6575.51 | L34: =L26+L27+L28+L29+L30+L31+L32+L33 -> 1087.6 | M34: =M26+M27+M28+M29+M30+M31+M32+M33 -> 7172.01 | N34: =N26+N27+N28+N29+N30+N31+N32+N33 -> 18641.19 | O34: =O26+O27+O28+O29+O30+O31+O32+O33 -> 291 | Q34: Total: | R34: =R26+R27+R28+R29+R30+R31+R32+R33 -> 5227.5 | S34: =S26+S27+S28+S29+S30+S31+S32+S33 -> 1243.1 | T34: =T26+T27+T28+T29+T30+T31+T32+T33 -> 5127.2 | U34: =U26+U27+U28+U29+U30+U31+U32+U33 -> 19946.89 | V34: =V26+V27+V28+V29+V30+V31+V32+V33 -> 227 | X34: Total: | Y34: =Y26+Y27+Y28+Y29+Y30+Y31+Y32+Y33 -> 4432 | Z34: =Z26+Z27+Z28+Z29+Z30+Z31+Z32+Z33 -> 357 | AA34: =AA26+AA27+AA28+AA29+AA30+AA31+AA32+AA33 -> 5562.18 | AB34: =AB26+AB27+AB28+AB29+AB30+AB31+AB32+AB33 -> 17988.28 | AC34: =AC26+AC27+AC28+AC29+AC30+AC31+AC32+AC33 -> 214 | AE34: Total: | AF34: =AF26+AF27+AF28+AF29+AF30+AF31+AF32+AF33 -> 7999.62 | AG34: =AG26+AG27+AG28+AG29+AG30+AG31+AG32+AG33 -> 2019.42 | AH34: =AH26+AH27+AH28+AH29+AH30+AH31+AH32+AH33 -> 9740.28 | AI34: =AI26+AI27+AI28+AI29+AI30+AI31+AI32+AI33 -> 20368.35 | AJ34: =AJ26+AJ27+AJ28+AJ29+AJ30+AJ31+AJ32+AJ33 -> 320 | AM34: Total: | AN34: =AN26+AN27+AN28+AN29+AN30+AN31+AN32+AN33 -> 24234.63 | AO34: =AO26+AO27+AO28+AO29+AO30+AO31+AO32+AO33 -> 4707.12 | AP34: =AP26+AP27+AP28+AP29+AP30+AP31+AP32+AP33 -> 27601.67 | AQ34: =AQ26+AQ27+AQ28+AQ29+AQ30+AQ31+AQ32+AQ33 -> 1052
C35: Faturado dia real | D35: =D34-E34 -> 0 | J35: Faturado dia real | K35: =K34-L34 -> 5487.91 | Q35: Faturado dia real | R35: =R34-S34 -> 3984.4 | X35: Faturado dia real | Y35: =Y34-Z34 -> 4075 | AE35: Faturado dia real | AF35: =AF34-AG34 -> 5980.2 | AM35: Fat. Real | AN35: =AN34-AO34 -> 19527.51
C36: Recebido dia real | D36: =F34-E34 -> 0 | J36: Recebido dia real | K36: =M34-L34 -> 6084.41 | Q36: Recebido dia real | R36: =T34-S34 -> 3884.1 | X36: Recebido dia real | Y36: =AA34-Z34 -> 5205.18 | AE36: Recebido dia real | AF36: =AH34-AG34 -> 7720.86
B37: Dia | C37: Lojas | D37: Faturamento dia | E37: Não pago dia | F37: Recebido dia | G37: Não pago Acumulado | H37: Peças | I37: Dia | J37: Lojas | K37: Faturamento | L37: Não pago dia | M37: Recebido dia | N37: Não pago Acumulado | O37: Peças | P37: Dia | Q37: Lojas | R37: Faturamento | S37: Não pago dia | T37: Recebido dia | U37: Não pago Acumulado | V37: Peças | W37: Dia | X37: Lojas | Y37: Faturamento | Z37: Não pago dia | AA37: Recebido dia | AB37: Não pago Acumulado | AC37: Peças | AD37: Dia | AE37: Lojas | AF37: Faturamento | AG37: Não pago dia | AH37: Recebido dia | AI37: Não pago Acumulado | AJ37: Peças | AM37: Lojas | AN37: Faturamento | AO37: Não pago dia | AP37: Recebido | AQ37: Peças
A38: Quinta-feira | C38: Lago Norte | I38: 45693 | J38: Lago Norte | K38: 668.91 | L38: 30 | M38: 713.91 | N38: 756 | O38: 30 | P38: 46065 | Q38: Lago Norte | R38: 394.8 | S38: 85 | T38: 339.8 | U38: 1876.4 | V38: 30 | W38: 46072 | X38: Lago Norte | Y38: 626 | Z38: 156 | AA38: 624.9 | AB38: 1016.9 | AC38: 17 | AD38: 46079 | AE38: Lago Norte | AF38: 417.8 | AG38: 0 | AH38: 482.8 | AI38: 1210.97 | AJ38: 21 | AL38: Faturamento Total das Quintas-feiras | AM38: Lago Norte | AN38: =D38+K38+R38+Y38+AF38 -> 2107.51 | AO38: =E38+L38+S38+Z38+AG38 -> 271 | AP38: =F38+M38+T38+AA38+AH38 -> 2161.41 | AQ38: =H38+O38+V38+AC38+AJ38 -> 98
C39: 202 Norte | J39: 202 Norte | K39: 1349.9 | L39: 0 | M39: 1349.9 | N39: 2413.4 | O39: 25 | Q39: 202 Norte | R39: 1673.2 | S39: 409.9 | T39: 1481.3 | U39: 1556.1 | V39: 54 | X39: 202 Norte | Y39: 338.8 | Z39: 109.8 | AA39: 229 | AB39: 1235.2 | AC39: 17 | AE39: 202 Norte | AF39: 670.9 | AG39: 0 | AH39: 670.9 | AI39: 3129.12 | AJ39: 20 | AM39: 202 Norte | AN39: =D39+K39+R39+Y39+AF39 -> 4032.8 | AO39: =E39+L39+S39+Z39+AG39 -> 519.7 | AP39: =F39+M39+T39+AA39+AH39 -> 3731.1 | AQ39: =H39+O39+V39+AC39+AJ39 -> 116
C40: 213 Norte | J40: 213 Norte | Q40: 213 Norte | X40: 213 Norte | AE40: 213 Norte | AM40: 213 Norte | AN40: =D40+K40+R40+Y40+AF40 -> 0 | AO40: =E40+L40+S40+Z40+AG40 -> 0 | AP40: =F40+M40+T40+AA40+AH40 -> 0 | AQ40: =H40+O40+V40+AC40+AJ40 -> 0
...

Sheet Meta faturamento 2025
A2: Meta Faturamento Maio
A4: Loja | B4: Fat. Anterior | C4: % a aumentar | E4: Meta Mês | F4: Valor faturado até o momento (dentro do mês) | H4: Valor que falta para atingir a meta | I4: Valor a ser faturado no dia para atingir a meta
A6: 202N | B6: ='Faturamento '!E40 -> 0 | C6: 0.1 | D6: =B6*C6 -> 0 | E6: =B6+D6 -> 0 | F6: ='Faturamento '!F40 -> 0 | H6: =E6-F6 -> 0 | I6: =H6/3 -> 0
A7: 213N | B7: ='Faturamento '!E41 -> 0 | C7: 0.1 | D7: =B7*C7 -> 0 | E7: =B7+D7 -> 0 | F7: ='Faturamento '!F41 -> 0 | H7: =E7-F7 -> 0 | I7: =H7/3 -> 0
A8: 307N | B8: ='Faturamento '!E42 -> 0 | C8: 0.1 | D8: =B8*C8 -> 0 | E8: =B8+D8 -> 0 | F8: ='Faturamento '!F42 -> 0 | H8: =E8-F8 -> 0 | I8: =H8/3 -> 0
A9: 313N | B9: ='Faturamento '!E43 -> 0 | C9: 0.1 | D9: =B9*C9 -> 0 | E9: =B9+D9 -> 0 | F9: ='Faturamento '!F43 -> 0 | H9: =E9-F9 -> 0 | I9: =H9/3 -> 0
A10: Lago | B10: ='Faturamento '!E45 -> 0 | C10: 0.1 | D10: =B10*C10 -> 0 | E10: =B10+D10 -> 0 | F10: ='Faturamento '!F45 -> 0 | H10: =E10-F10 -> 0 | I10: =H10/3 -> 0
A11: Noroeste | B11: ='Faturamento '!E47 -> 0 | C11: 0.1 | D11: =B11*C11 -> 0 | E11: =B11+D11 -> 0 | F11: ='Faturamento '!F47 -> 0 | H11: =E11-F11 -> 0 | I11: =H11/3 -> 0
A12: Sudoeste | B12: ='Faturamento '!E46 -> 0 | C12: 0.2 | D12: =B12*C12 -> 0 | E12: =B12+D12 -> 0 | F12: ='Faturamento '!F46 -> 0 | H12: =E12-F12 -> 0 | I12: =H12/3 -> 0
A16: Meta Faturamento Junho
A18: Loja | B18: Fat. Anterior | C18: % a aumentar | E18: Meta Mês | F18: Valor faturado até o momento (dentro do mês) | H18: Valor que falta para atingir a meta | I18: Valor a ser faturado no dia para atingir a meta
A20: 202N | B20: ='Faturamento '!F40 -> 0 | C20: 0.1 | D20: =B20*C20 -> 0 | E20: =B20+D20 -> 0 | F20: ='Faturamento '!G40 -> 0 | H20: =E20-F20 -> 0 | I20: =H20/3 -> 0 | J20: Meta batida (receberá 100% = 1% do faturamento)
A21: 213N | B21: ='Faturamento '!F41 -> 0 | C21: 0.1 | D21: =B21*C21 -> 0 | E21: =B21+D21 -> 0 | F21: ='Faturamento '!G41 -> 0 | H21: =E21-F21 -> 0 | I21: =H21/3 -> 0
A22: 307N | B22: ='Faturamento '!F42 -> 0 | C22: 0.1 | D22: =B22*C22 -> 0 | E22: =B22+D22 -> 0 | F22: ='Faturamento '!G42 -> 0 | H22: =E22-F22 -> 0 | I22: =H22/3 -> 0
A23: 313N | B23: ='Faturamento '!F43 -> 0 | C23: 0.1 | D23: =B23*C23 -> 0 | E23: =B23+D23 -> 0 | F23: ='Faturamento '!G43 -> 0 | H23: =E23-F23 -> 0 | I23: =H23/3 -> 0 | J23: Receberá valor proporcional, 94,56% = 0,9456% do faturamento.
A24: Lago | B24: ='Faturamento '!F45 -> 0 | C24: 0.1 | D24: =B24*C24 -> 0 | E24: =B24+D24 -> 0 | F24: ='Faturamento '!G45 -> 0 | H24: =E24-F24 -> 0 | I24: =H24/3 -> 0
A25: Noroeste | B25: ='Faturamento '!F47 -> 0 | C25: 0.1 | D25: =B25*C25 -> 0 | E25: =B25+D25 -> 0 | F25: ='Faturamento '!G47 -> 0 | H25: =E25-F25 -> 0 | I25: =H25/3 -> 0 | J25: Meta batida (receberá 100% = 1% do faturamento)
A26: Sudoeste | B26: ='Faturamento '!F46 -> 0 | C26: 0.1 | D26: =B26*C26 -> 0 | E26: =B26+D26 -> 0 | F26: ='Faturamento '!G46 -> 0 | H26: =E26-F26 -> 0 | I26: =H26/3 -> 0 | J26: Meta batida (receberá 100% = 1% do faturamento)
A30: Meta Dani | B30: R$ 21.890,98 | E30: 21890.98 | F30: =Jun!D63+Jun!K8+Jun!K30+Jun!K52+Jun!K74+Jun!R19+Jun!R41+Jun!R63+Jun!Y8+Jun!Y30+Jun!AF19+Jun!AF41+Jun!AF63+456 -> #REF! | H30: =E30-F30 -> #REF! | J30: =F30*10% -> #REF!
A31: Meta Ingrid | B31: R$ 17.090,24 | E31: 17090.24 | F31: =Jun!D74+Jun!K19+Jun!K41+Jun!K63+Jun!R8+Jun!R30+Jun!R52+Jun!R74+Jun!Y19+Jun!Y41+Jun!Y52+Jun!Y63+Jun!AF8+Jun!AF30+Jun!AF52+Jun!AF74 -> #REF! | H31: =E31-F31 -> #REF! | J31: =F31*10% -> #REF!
F33: =F30+F31 -> #REF!
F34: =F25-F33 -> #REF! | G34: Luana
A39: Meta Faturamento Julho
A41: Loja | B41: Fat. Anterior | C41: % a aumentar | E41: Meta Mês | F41: Valor faturado até o momento (dentro do mês) | H41: Valor que falta para atingir a meta | I41: Valor a ser faturado no dia para atingir a meta
A43: 202N | B43: ='Faturamento '!G40 -> 0 | C43: 0.1 | D43: =B43*C43 -> 0 | E43: =B43+D43 -> 0 | F43: ='Faturamento '!H40 -> 0 | H43: =F43-E43 -> 0 | I43: =H43/3 -> 0 | J43: =F43*100/E43 -> #DIV/0!
A44: 213N | B44: ='Faturamento '!G41 -> 0 | C44: 0.1 | D44: =B44*C44 -> 0 | E44: =B44+D44 -> 0 | F44: ='Faturamento '!H41 -> 0 | H44: =F44-E44 -> 0 | I44: =H44/3 -> 0 | J44: =F44*100/E44 -> #DIV/0!
A45: 307N | B45: ='Faturamento '!G42 -> 0 | C45: 0.1 | D45: =B45*C45 -> 0 | E45: =B45+D45 -> 0 | F45: ='Faturamento '!H42 -> 0 | H45: =F45-E45 -> 0 | I45: =H45/3 -> 0 | J45: =F45*100/E45 -> #DIV/0!
A46: 313N | B46: ='Faturamento '!G43 -> 0 | C46: 0.1 | D46: =B46*C46 -> 0 | E46: =B46+D46 -> 0 | F46: ='Faturamento '!H43 -> 0 | H46: =F46-E46 -> 0 | I46: =H46/3 -> 0 | J46: =F46*100/E46 -> #DIV/0!
A47: Lago | B47: ='Faturamento '!G45 -> 0 | C47: 0.1 | D47: =B47*C47 -> 0 | E47: =B47+D47 -> 0 | F47: ='Faturamento '!H45 -> 0 | H47: =F47-E47 -> 0 | I47: =H47/3 -> 0 | J47: =F47*100/E47 -> #DIV/0!
A48: Noroeste | B48: ='Faturamento '!G47 -> 0 | C48: 0.1 | D48: =B48*C48 -> 0 | E48: =B48+D48+0.01 -> 0.01 | F48: ='Faturamento '!H47 -> 0 | H48: =F48-E48 -> -0.01 | I48: =H48/3 -> -0.0033333333 | J48: =F48*100/E48 -> 0
A49: Sudoeste | B49: ='Faturamento '!G46 -> 0 | C49: 0.1 | D49: =B49*C49 -> 0 | E49: =B49+D49 -> 0 | F49: ='Faturamento '!H46 -> 0 | H49: =F49-E49 -> 0 | I49: =H49/3 -> 0 | J49: =F49*100/E49 -> #DIV/0!
A51: Meta Dani | B51: =F30 -> #REF! | E51: =#REF! -> #REF! | F51: =Jul!D8+Jul!D30+Jul!D52+Jul!D74+Jul!K19+Jul!K41+Jul!K63+Jul!R8+Jul!R30+Jul!R63+Jul!R74+Jul!Y19+Jul!Y41+Jul!Y63+Jul!AF8+Jul!AF30 -> #REF! | H51: =F51-E51 -> #REF! | J51: =F51*100/E51 -> #REF!
A52: Meta Ingrid | B52: =F31 -> #REF! | E52: =#REF! -> #REF! | F52: =Jul!D19+Jul!D41+Jul!D63+Jul!K8+Jul!K30+Jul!K52+Jul!K74+Jul!R19+Jul!R41+Jul!R52+Jul!Y8+Jul!Y30+Jul!Y52+Jul!AF19 -> #REF! | H52: =F52-E52 -> #REF! | J52: =F52*100/E52 -> #REF!
A56: Meta Faturamento Agosto
A58: Loja | B58: Fat. Anterior | C58: % a aumentar | E58: Meta Mês | F58: Valor faturado até o momento (dentro do mês) | H58: Valor que falta para atingir a meta | I58: Valor a ser faturado no dia para atingir a meta
A60: 202N | B60: ='Faturamento '!H40 -> 0 | C60: 0.1 | D60: =B60*C60 -> 0 | E60: =B60+D60 -> 0 | F60: ='Faturamento '!I40 -> 0 | H60: =F60-E60 -> 0 | I60: =H60/3 -> 0
A61: 213N | B61: ='Faturamento '!H41 -> 0 | C61: 0.1 | D61: =B61*C61 -> 0 | E61: =B61+D61 -> 0 | F61: ='Faturamento '!I41 -> 0 | H61: =F61-E61 -> 0 | I61: =H61/3 -> 0 | J61: 197.54
A62: 307N | B62: ='Faturamento '!H42 -> 0 | C62: 0.05 | D62: =B62*C62 -> 0 | E62: =B62+D62 -> 0 | F62: ='Faturamento '!I42 -> 0 | H62: =F62-E62 -> 0 | I62: =H62/3 -> 0
A63: 313N | B63: ='Faturamento '!H43 -> 0 | C63: 0.1 | D63: =B63*C63 -> 0 | E63: =B63+D63 -> 0 | F63: ='Faturamento '!I43 -> 0 | H63: =F63-E63 -> 0 | I63: =H63/3 -> 0
A64: 314S | E64: 5000 | F64: ='Faturamento '!I44 -> 0 | H64: =F64-E64 -> -5000
...

Sheet Mar
B1: Dia | C1: Lojas | D1: Faturamento dia | E1: Não pago dia | F1: Recebido dia | G1: Não pago Acumulado | H1: Peças | I1: Dia | J1: Lojas | K1: Faturamento | L1: Não pago dia | M1: Recebido dia | N1: Não pago Acumulado | O1: Peças | P1: Dia | Q1: Lojas | R1: Faturamento | S1: Não pago dia | T1: Recebido dia | U1: Não pago Acumulado | V1: Peças | W1: Dia | X1: Lojas | Y1: Faturamento | Z1: Não pago dia | AA1: Recebido dia | AB1: Não pago Acumulado | AC1: Peças | AD1: Dia | AE1: Lojas | AF1: Faturamento | AG1: Não pago dia | AH1: Recebido dia | AI1: Não pago Acumulado | AJ1: Peças | AM1: Lojas | AN1: Faturamento | AO1: Não pago dia | AP1: Recebido | AQ1: Peças
A2: Segunda-feira | B2: 45747 | C2: Lago Norte | I2: 45719 | J2: Lago Norte | P2: 45726 | Q2: Lago Norte | W2: 45733 | X2: Lago Norte | AD2: 45740 | AE2: Lago Norte | AL2: Faturamento Total das Segundas-feiras | AM2: Lago Norte | AN2: =D2+K2+R2+Y2+AF2 -> 0 | AO2: =E2+L2+S2+Z2+AG2 -> 0 | AP2: =F2+M2+T2+AA2+AH2 -> 0 | AQ2: =H2+O2+V2+AC2+AJ2 -> 0
C3: 202 Norte | J3: 202 Norte | Q3: 202 Norte | X3: 202 Norte | AE3: 202 Norte | AM3: 202 Norte | AN3: =D3+K3+R3+Y3+AF3 -> 0 | AO3: =E3+L3+S3+Z3+AG3 -> 0 | AP3: =F3+M3+T3+AA3+AH3 -> 0 | AQ3: =H3+O3+V3+AC3+AJ3 -> 0
C4: 213 Norte | J4: 213 Norte | Q4: 213 Norte | X4: 213 Norte | AE4: 213 Norte | AM4: 213 Norte | AN4: =D4+K4+R4+Y4+AF4 -> 0 | AO4: =E4+L4+S4+Z4+AG4 -> 0 | AP4: =F4+M4+T4+AA4+AH4 -> 0 | AQ4: =H4+O4+V4+AC4+AJ4 -> 0
C5: 307 Norte | J5: 307 Norte | Q5: 307 Norte | X5: 307 Norte | AE5: 307 Norte | AM5: 307 Norte | AN5: =D5+K5+R5+Y5+AF5 -> 0 | AO5: =E5+L5+S5+Z5+AG5 -> 0 | AP5: =F5+M5+T5+AA5+AH5 -> 0 | AQ5: =H5+O5+V5+AC5+AJ5 -> 0
C6: 313 Norte | J6: 313 Norte | Q6: 313 Norte | X6: 313 Norte | AE6: 313 Norte | AM6: 313 Norte | AN6: =D6+K6+R6+Y6+AF6 -> 0 | AO6: =E6+L6+S6+Z6+AG6 -> 0 | AP6: =F6+M6+T6+AA6+AH6 -> 0 | AQ6: =H6+O6+V6+AC6+AJ6 -> 0
C7: 314 Sul | J7: 314 Sul | Q7: 314 Sul | X7: 314 Sul | AE7: 314 Sul | AM7: 314 Sul | AN7: =D7+K7+R7+Y7+AF7 -> 0 | AO7: =E7+L7+S7+Z7+AG7 -> 0 | AP7: =F7+M7+T7+AA7+AH7 -> 0 | AQ7: =H7+O7+V7+AC7+AJ7 -> 0
C8: Sudoeste | J8: Sudoeste | Q8: Sudoeste | X8: Sudoeste | AE8: Sudoeste | AM8: Sudoeste | AN8: =D8+K8+R8+Y8+AF8 -> 0 | AO8: =E8+L8+S8+Z8+AG8 -> 0 | AP8: =F8+M8+T8+AA8+AH8 -> 0 | AQ8: =H8+O8+V8+AC8+AJ8 -> 0
C9: Noroeste | J9: Noroeste | Q9: Noroeste | X9: Noroeste | AE9: Noroeste | AM9: Noroeste | AN9: =D9+K9+R9+Y9+AF9 -> 0 | AO9: =E9+L9+S9+Z9+AG9 -> 0 | AP9: =F9+M9+T9+AA9+AH9 -> 0 | AQ9: =H9+O9+V9+AC9+AJ9 -> 0
